Workbook

Sheet low avg budget & poplarity
A1: Years (Release Date) | B1: (Multiple Items)
A3: Row Labels | B3: Average of Movie FB Likes | C3: Average of IMDb Score (1-10) | D3: Average of Budget
A4: Horror | B4: 10134.938 | C4: 5.6148148 | D4: 13306914
A5: Biography | B5: 18670.169 | C5: 7.0788136 | D5: 25454237
A6: Drama | B6: 14965.734 | C6: 6.7473988 | D6: 31003423
A7: Comedy | B7: 7798.5207 | C7: 6.1074074 | D7: 50957133
A8: Crime | B8: 14144.435 | C8: 6.8194444 | D8: 64732557
A9: Adventure | B9: 22174.01 | C9: 6.5589744 | D9: 78553077
A10: Action | B10: 20679.96 | C10: 6.3162791 | D10: 82117926
A11: Grand Total | B11: 15270.921 | C11: 6.4245826 | D11: 55162719

Sheet Low-Risk Investment Indicators 
A1: Years (Release Date) | B1: (Multiple Items)
A2: IMDb Score (1-10) | B2: (Multiple Items) | C2: AVERAGE = 6.43
A4: Row Labels | B4: Count of Title | C4: Average of ROI | D4: Average of Lead Actor FB Likes | E4: Average of IMDb Score (1-10) | F4: =_xlfn.PERCENTILE.EXC(B4:B892,0.25) -> 1
A5: Robert Downey Jr. | B5: 15 | C5: 0.32498085 | D5: 21000 | E5: 7.22 | F5: =_xlfn.PERCENTILE.EXC(B4:B892,0.75) -> 2
A6: Matt Damon | B6: 13 | C6: 0.28724496 | D6: 13000 | E6: 7.0461538
A7: J.K. Simmons | B7: 13 | C7: 2.2867593 | D7: 24000 | E7: 7.1769231
A8: Jennifer Lawrence | B8: 12 | C8: 2.5739128 | D8: 34000 | E8: 7.1916667
A9: Leonardo DiCaprio | B9: 11 | C9: 0.20826122 | D9: 29000 | E9: 7.8636364
A10: Christian Bale | B10: 11 | C10: 0.14632248 | D10: 23000 | E10: 7.5909091
A11: Joseph Gordon-Levitt | B11: 10 | C11: 1.3438164 | D11: 23000 | E11: 7.08
A12: Jason Statham | B12: 10 | C12: 0.16937579 | D12: 26000 | E12: 6.74
A13: Hugh Jackman | B13: 10 | C13: 0.004065743 | D13: 20000 | E13: 7.12
A14: Johnny Depp | B14: 10 | C14: 0.17351894 | D14: 40000 | E14: 6.94
A15: Ryan Gosling | B15: 9 | C15: 1.124123 | D15: 33000 | E15: 7.3444444
A16: Denzel Washington | B16: 9 | C16: 0.65302025 | D16: 18000 | E16: 7.1888889
A17: Gerard Butler | B17: 9 | C17: 0.45611238 | D17: 18000 | E17: 7.2555556
... A121: Olivia Wilde | B121: 2 | C121: -0.2769055 | D121: 10000 | E121: 7.25
A122: (blank) | B122: 2 | C122: -0.98766887 | E122: 7.3
A123: Don Cheadle | B123: 2 | C123: 0.24530742 | D123: 3000 | E123: 7
A124: Jet Li | B124: 2 | C124: -0.77074875 | D124: 5000 | E124: 6.85
A125: Amy Poehler | B125: 2 | C125: 0.58510427 | D125: 1000 | E125: 7.4
A126: Bella Thorne | B126: 2 | C126: 1.5795566 | D126: 35000 | E126: 6.5
A127: Jimmy Bennett | B127: 2 | C127: -0.65391578 | D127: 87000 | E127: 6.65
A128: Al Pacino | B128: 2 | C128: -0.043499062 | D128: 14000 | E128: 7
A129: Hunter Parrish | B129: 2 | C129: -0.093465301 | D129: 2000 | E129: 7
A130: Billy Crudup | B130: 2 | C130: 0.1284485 | D130: 745 | E130: 7.8
A131: Jennifer Jason Leigh | B131: 2 | C131: -0.67618356 | D131: 1000 | E131: 7.2
A132: Bob Hoskins | B132: 2 | C132: -0.64811146 | D132: 5000 | E132: 7.15
A133: Jim Parsons | B133: 2 | C133: -0.044135574 | D133: 17000 | E133: 6.7
A134: Bojana Novakovic | B134: 2 | C134: -0.028475727 | D134: 2000 | E134: 6.6
... A527: Grand Total | B527: 994 | C527: 0.97648194 | D527: 9182.5202 | E527: 7.156841

Sheet Detail1
A1: Details for Count of Title - Director Name: Edward Burns
A3: Title | B3: Lead Actor | C3: Director Name | D3: Lead Actor FB Likes | E3: Cast FB Likes | F3: Director FB Likes | G3: Movie FB Likes | H3: IMDb Score (1-10) | I3: Total Reviews | J3: Duration (min) | K3: Gross Revenue | L3: Budget | M3: Release Date | N3: Color/B&W | O3: Genre | P3: Language | Q3: Country | R3: Rating | S3: Is _English | T3: Profit | U3: %Profit | V3: Duration_Class | W3: ROI
A4: The Brothers McMullen | B4: Shari Albert | C4: Edward Burns | D4: 138 | E4: 388 | F4: 0 | G4: 265 | H4: 6.6 | I4: 36 | J4: 98 | K4: 10246600 | L4: 25000 | M4: 34894 | N4: Color | O4: Comedy | P4: English | Q4: USA | R4: R | S4: English | T4: 10221600 | U4: 408.864 | V4: 90-110 minutes | W4: 408.864
A5: She's the One | B5: John Mahoney | C5: Edward Burns | D5: 385 | E5: 995 | F5: 0 | G5: 453 | H5: 6.1 | I5: 43 | J5: 96 | K5: 9449219 | L5: 3500000 | M5: 35418 | N5: Color | O5: Comedy | P5: English | Q5: USA | R5: R | S5: English | T5: 5949219 | U5: 1.6997769 | V5: 90-110 minutes | W5: 1.6997769
A6: Newlyweds | B6: Kerry BishÃ© | C6: Edward Burns | D6: 296 | E6: 690 | F6: 0 | G6: 413 | H6: 6.4 | I6: 14 | J6: 95 | K6: 4584 | L6: 9000 | M6: 40842 | N6: Color | O6: Comedy | P6: English | Q6: USA | R6: Not Rated | S6: English | T6: -4416 | U6: -0.49066667 | V6: 90-110 minutes | W6: -0.49066667

Sheet Director And IMDB Score
A1: Years (Release Date) | B1: (Multiple Items)
A3: Director Name | B3: Average of IMDb Score (1-10) | C3: Average of ROI | D3: StdDev of ROI | E3: Count of Title | H3: Years | I3: 1990-2015
A4: Clint Eastwood | B4: 7.2764706 | C4: 1.0862411 | D4: 2.0554456 | E4: 17 | H4: Min Number of Movies | I4: 4
A5: Steven Spielberg | B5: 7.4117647 | C5: 1.1340741 | D5: 1.3903771 | E5: 17 | H5: Min IMDB Score | I5: 6.5
A6: Woody Allen | B6: 6.93125 | C6: 0.010409785 | D6: 0.93657553 | E6: 16 | H6: Min ROI | I6: positive
A7: Steven Soderbergh | B7: 6.6428571 | C7: 1.3635791 | D7: 4.0598708 | E7: 14 | H7: Max Std of ROI | I7: 6.5
A8: Ron Howard | B8: 6.9916667 | C8: 0.28798214 | D8: 0.93598558 | E8: 12
A9: Spike Lee | B9: 6.7333333 | C9: 1.0449355 | D9: 3.4306194 | E9: 12
A10: Tim Burton | B10: 6.9666667 | C10: 0.33310321 | D10: 0.69465899 | E10: 12
A11: Martin Scorsese | B11: 7.7083333 | C11: 0.074941928 | D11: 0.63502066 | E11: 12
A12: Robert Zemeckis | B12: 7.1545455 | C12: 0.73393797 | D12: 1.7089597 | E12: 11
A13: Chris Columbus | B13: 6.6545455 | C13: 3.1116612 | D13: 5.0576461 | E13: 11
A14: Michael Bay | B14: 6.5454545 | C14: 0.68057582 | D14: 0.79293059 | E14: 11
A15: David Fincher | B15: 7.75 | C15: 0.5352296 | D15: 0.93079326 | E15: 10
A16: Peter Jackson | B16: 7.8888889 | C16: 0.91105002 | D16: 1.3628213 | E16: 9
A17: Sam Raimi | B17: 6.8666667 | C17: 0.30001014 | D17: 0.71659868 | E17: 9
A18: Brett Ratner | B18: 6.4555556 | C18: 0.22013405 | D18: 0.58333466 | E18: 9
A19: Phillip Noyce | B19: 6.7666667 | C19: 0.1947126 | D19: 0.60540533 | E19: 9
... A118: Grand Total | B118: 7.0144476 | C118: 0.88193795 | D118: 2.0242907 | E118: 706

Sheet Sheet4
A1: Years (Release Date) | B1: (Multiple Items)
A3: Row Labels | B3: Average of ROI | C3: StdDev of ROI | D3: Count of Title
A4: R | B4: 7.4212967 | C4: 213.35567 | D4: 1138
A5: PG | B5: 1.9363193 | C5: 13.161323 | D5: 377
A6: G | B6: 0.79352176 | C6: 1.7814767 | D6: 54
A7: PG-13 | B7: 0.74566813 | C7: 3.0877623 | D7: 1026
A8: NC-17 | B8: -0.14219128 | C8: 0.68513344 | D8: 3
A9: Grand Total | B9: 3.8425355 | C9: 141.31019 | D9: 2598

Sheet Budget tier good invetment
A1: Years (Release Date) | B1: (Multiple Items)
A3: Row Labels | B3: Count of Title | C3: Average of Good_Investment | D3: Average of ROI | E3: StdDev of ROI
A4: High | B4: 709 | C4: 0.24682652 | D4: 0.12221871 | E4: 0.8391676
A5: Mid | B5: 1386 | C5: 0.34776335 | D5: 0.42800722 | E5: 1.4814131
A6: Low | B6: 594 | C6: 0.39393939 | D6: 20.287267 | E6: 315.48691
A7: Grand Total | B7: 2689 | C7: 0.33134994 | D7: 4.7342908 | E7: 148.41734

Sheet Main
A1: Title | B1: Lead Actor | C1: Director Name | D1: Lead Actor FB Likes | E1: Cast FB Likes | F1: Director FB Likes | G1: Movie FB Likes | H1: IMDb Score (1-10) | I1: Total Reviews | J1: Duration (min) | K1: Gross Revenue | L1: Budget | M1: Release Date | N1: Color/B&W | O1: Genre | P1: Language | Q1: Country | R1: Rating | S1: Is _English | T1: Profit | U1: %Profit | V1: Duration_Class | W1: ROI | X1: Budget Tier | Y1: Good_Investment
A2: [Rec] 2 | B2: Jonathan D. Mellor | C2: Jaume BalaguerÃ³ | D2: 37 | E2: 73 | F2: 57 | G2: 4000 | H2: 6.6 | I2: 222 | J2: 85 | K2: 27024 | L2: 5600000 | M2: =VLOOKUP(A2,Sheet2!$A$1:G3726,2,0) -> 39921 | N2: =VLOOKUP(A2,Sheet2!$A$1:G3726,3,0) -> Color | O2: =VLOOKUP(A2,Sheet2!$A$1:G3726,4,0) -> Horror | P2: =VLOOKUP(A2,Sheet2!$A$1:G3726,5,0) -> Spanish | Q2: =VLOOKUP(A2,Sheet2!$A$1:G3726,6,0) -> Spain | R2: =VLOOKUP(A2,Sheet2!$A$1:G3726,7,0) -> R | S2: =IF(Table1[[#This Row],[Language]]="English","English","Other language") -> Other language | T2: =Table1[[#This Row],[Gross Revenue]]-Table1[[#This Row],[Budget]] -> -5572976 | U2: =(Table1[[#This Row],[Gross Revenue]]/Table1[[#This Row],[Budget]])-1 -> -0.99517429 | V2: =IF(J2="","",IF(J2<90,"<90 minutes",IF(J2<=110,"90-110 minutes",IF(J2<=130,"111-130 minutes",IF(J2<=150,"131-150 minutes",">150 minutes"))))) -> <90 minutes | W2: =Table1[[#This Row],[Profit]]/Table1[[#This Row],[Budget]] -> -0.99517429 | X2: =IF(L2="","", IF(L2<Predictability!$B$1,"Low", IF(L2<=Predictability!$B$2,"Mid","High"))) -> Low | Y2: =IF(W2>=0.5,1,0) -> 0 | Z2: =CORREL(Table1[IMDb Score (1-10)],Table1[ROI]) -> 0.0087393311
A3: 10 Days in a Madhouse | B3: Christopher Lambert | C3: Timothy Hines | D3: 1000 | E3: 2059 | F3: 0 | G3: 26000 | H3: 7.5 | I3: 1 | J3: 111 | K3: 14616 | L3: 12000000 | M3: =VLOOKUP(A3,Sheet2!$A$1:G3727,2,0) -> 42130 | N3: =VLOOKUP(A3,Sheet2!$A$1:G3727,3,0) -> Color | O3: =VLOOKUP(A3,Sheet2!$A$1:G3727,4,0) -> Drama | P3: =VLOOKUP(A3,Sheet2!$A$1:G3727,5,0) -> English | Q3: =VLOOKUP(A3,Sheet2!$A$1:G3727,6,0) -> USA | R3: =VLOOKUP(A3,Sheet2!$A$1:G3727,7,0) -> R | S3: =IF(Table1[[#This Row],[Language]]="English","English","Other language") -> English | T3: =Table1[[#This Row],[Gross Revenue]]-Table1[[#This Row],[Budget]] -> -11985384 | U3: =(Table1[[#This Row],[Gross Revenue]]/Table1[[#This Row],[Budget]])-1 -> -0.998782 | V3: =IF(J3="","",IF(J3<90,"<90 minutes",IF(J3<=110,"90-110 minutes",IF(J3<=130,"111-130 minutes",IF(J3<=150,"131-150 minutes",">150 minutes"))))) -> 111-130 minutes | W3: =Table1[[#This Row],[Profit]]/Table1[[#This Row],[Budget]] -> -0.998782 | X3: =IF(L3="","", IF(L3<Predictability!$B$1,"Low", IF(L3<=Predictability!$B$2,"Mid","High"))) -> Mid | Y3: =IF(W3>=0.5,1,0) -> 0
A4: 10 Things I Hate About You | B4: Joseph Gordon-Levitt | C4: Gil Junger | D4: 23000 | E4: 37907 | F4: 19 | G4: 10000 | H4: 7.2 | I4: 133 | J4: 97 | K4: 38176108 | L4: 16000000 | M4: =VLOOKUP(A4,Sheet2!$A$1:G3728,2,0) -> 36245 | N4: =VLOOKUP(A4,Sheet2!$A$1:G3728,3,0) -> Color | O4: =VLOOKUP(A4,Sheet2!$A$1:G3728,4,0) -> Comedy | P4: =VLOOKUP(A4,Sheet2!$A$1:G3728,5,0) -> English | Q4: =VLOOKUP(A4,Sheet2!$A$1:G3728,6,0) -> USA | R4: =VLOOKUP(A4,Sheet2!$A$1:G3728,7,0) -> PG-13 | S4: =IF(Table1[[#This Row],[Language]]="English","English","Other language") -> English | T4: =Table1[[#This Row],[Gross Revenue]]-Table1[[#This Row],[Budget]] -> 22176108 | U4: =(Table1[[#This Row],[Gross Revenue]]/Table1[[#This Row],[Budget]])-1 -> 1.3860067 | V4: =IF(J4="","",IF(J4<90,"<90 minutes",IF(J4<=110,"90-110 minutes",IF(J4<=130,"111-130 minutes",IF(J4<=150,"131-150 minutes",">150 minutes"))))) -> 90-110 minutes | W4: =Table1[[#This Row],[Profit]]/Table1[[#This Row],[Budget]] -> 1.3860067 | X4: =IF(L4="","", IF(L4<Predictability!$B$1,"Low", IF(L4<=Predictability!$B$2,"Mid","High"))) -> Mid | Y4: =IF(W4>=0.5,1,0) -> 1
A5: 102 Dalmatians | B5: Ioan Gruffudd | C5: Kevin Lima | D5: 2000 | E5: 4182 | F5: 36 | G5: 372 | H5: 4.8 | I5: 84 | J5: 100 | K5: 66941559 | L5: 85000000 | M5: =VLOOKUP(A5,Sheet2!$A$1:G3729,2,0) -> 36715 | N5: =VLOOKUP(A5,Sheet2!$A$1:G3729,3,0) -> Color | O5: =VLOOKUP(A5,Sheet2!$A$1:G3729,4,0) -> Adventure | P5: =VLOOKUP(A5,Sheet2!$A$1:G3729,5,0) -> English | Q5: =VLOOKUP(A5,Sheet2!$A$1:G3729,6,0) -> USA | R5: =VLOOKUP(A5,Sheet2!$A$1:G3729,7,0) -> G | S5: =IF(Table1[[#This Row],[Language]]="English","English","Other language") -> English | T5: =Table1[[#This Row],[Gross Revenue]]-Table1[[#This Row],[Budget]] -> -18058441 | U5: =(Table1[[#This Row],[Gross Revenue]]/Table1[[#This Row],[Budget]])-1 -> -0.21245225 | V5: =IF(J5="","",IF(J5<90,"<90 minutes",IF(J5<=110,"90-110 minutes",IF(J5<=130,"111-130 minutes",IF(J5<=150,"131-150 minutes",">150 minutes"))))) -> 90-110 minutes | W5: =Table1[[#This Row],[Profit]]/Table1[[#This Row],[Budget]] -> -0.21245225 | X5: =IF(L5="","", IF(L5<Predictability!$B$1,"Low", IF(L5<=Predictability!$B$2,"Mid","High"))) -> High | Y5: =IF(W5>=0.5,1,0) -> 0
A6: 10th & Wolf | B6: Brian Dennehy | C6: Robert Moresco | D6: 954 | E6: 2512 | F6: 53 | G6: 294 | H6: 6.4 | I6: 26 | J6: 107 | K6: 53481 | L6: 8000000 | M6: =VLOOKUP(A6,Sheet2!$A$1:G3730,2,0) -> 38850 | N6: =VLOOKUP(A6,Sheet2!$A$1:G3730,3,0) -> Color | O6: =VLOOKUP(A6,Sheet2!$A$1:G3730,4,0) -> Crime | P6: =VLOOKUP(A6,Sheet2!$A$1:G3730,5,0) -> English | Q6: =VLOOKUP(A6,Sheet2!$A$1:G3730,6,0) -> USA | R6: =VLOOKUP(A6,Sheet2!$A$1:G3730,7,0) -> R | S6: =IF(Table1[[#This Row],[Language]]="English","English","Other language") -> English | T6: =Table1[[#This Row],[Gross Revenue]]-Table1[[#This Row],[Budget]] -> -7946519 | U6: =(Table1[[#This Row],[Gross Revenue]]/Table1[[#This Row],[Budget]])-1 -> -0.99331488 | V6: =IF(J6="","",IF(J6<90,"<90 minutes",IF(J6<=110,"90-110 minutes",IF(J6<=130,"111-130 minutes",IF(J6<=150,"131-150 minutes",">150 minutes"))))) -> 90-110 minutes | W6: =Table1[[#This Row],[Profit]]/Table1[[#This Row],[Budget]] -> -0.99331488 | X6: =IF(L6="","", IF(L6<Predictability!$B$1,"Low", IF(L6<=Predictability!$B$2,"Mid","High"))) -> Low | Y6: =IF(W6>=0.5,1,0) -> 0
A7: 12 Rounds | B7: Taylor Cole | C7: Renny Harlin | D7: 969 | E7: 2799 | F7: 212 | G7: 0 | H7: 5.6 | I7: 113 | J7: 108 | K7: 12232937 | L7: 22000000 | M7: =VLOOKUP(A7,Sheet2!$A$1:G3731,2,0) -> 40137 | N7: =VLOOKUP(A7,Sheet2!$A$1:G3731,3,0) -> Color | O7: =VLOOKUP(A7,Sheet2!$A$1:G3731,4,0) -> Action | P7: =VLOOKUP(A7,Sheet2!$A$1:G3731,5,0) -> English | Q7: =VLOOKUP(A7,Sheet2!$A$1:G3731,6,0) -> USA | R7: =VLOOKUP(A7,Sheet2!$A$1:G3731,7,0) -> PG-13 | S7: =IF(Table1[[#This Row],[Language]]="English","English","Other language") -> English | T7: =Table1[[#This Row],[Gross Revenue]]-Table1[[#This Row],[Budget]] -> -9767063 | U7: =(Table1[[#This Row],[Gross Revenue]]/Table1[[#This Row],[Budget]])-1 -> -0.44395741 | V7: =IF(J7="","",IF(J7<90,"<90 minutes",IF(J7<=110,"90-110 minutes",IF(J7<=130,"111-130 minutes",IF(J7<=150,"131-150 minutes",">150 minutes"))))) -> 90-110 minutes | W7: =Table1[[#This Row],[Profit]]/Table1[[#This Row],[Budget]] -> -0.44395741 | X7: =IF(L7="","", IF(L7<Predictability!$B$1,"Low", IF(L7<=Predictability!$B$2,"Mid","High"))) -> Mid | Y7: =IF(W7>=0.5,1,0) -> 0
A8: 12 Years a Slave | B8: QuvenzhanÃ© Wallis | C8: Steve McQueen | D8: 2000 | E8: 4251 | F8: 0 | G8: 83000 | H8: 8.1 | I8: 597 | J8: 134 | K8: 56667870 | L8: 20000000 | M8: =VLOOKUP(A8,Sheet2!$A$1:G3732,2,0) -> 41587 | N8: =VLOOKUP(A8,Sheet2!$A$1:G3732,3,0) -> Color | O8: =VLOOKUP(A8,Sheet2!$A$1:G3732,4,0) -> Biography | P8: =VLOOKUP(A8,Sheet2!$A$1:G3732,5,0) -> English | Q8: =VLOOKUP(A8,Sheet2!$A$1:G3732,6,0) -> USA | R8: =VLOOKUP(A8,Sheet2!$A$1:G3732,7,0) -> R | S8: =IF(Table1[[#This Row],[Language]]="English","English","Other language") -> English | T8: =Table1[[#This Row],[Gross Revenue]]-Table1[[#This Row],[Budget]] -> 36667870 | U8: =(Table1[[#This Row],[Gross Revenue]]/Table1[[#This Row],[Budget]])-1 -> 1.8333935 | V8: =IF(J8="","",IF(J8<90,"<90 minutes",IF(J8<=110,"90-110 minutes",IF(J8<=130,"111-130 minutes",IF(J8<=150,"131-150 minutes",">150 minutes"))))) -> 131-150 minutes | W8: =Table1[[#This Row],[Profit]]/Table1[[#This Row],[Budget]] -> 1.8333935 | X8: =IF(L8="","", IF(L8<Predictability!$B$1,"Low", IF(L8<=Predictability!$B$2,"Mid","High"))) -> Mid | Y8: =IF(W8>=0.5,1,0) -> 1
A9: 127 Hours | B9: James Franco | C9: Danny Boyle | D9: 11000 | E9: 11984 | F9: 0 | G9: 63000 | H9: 7.6 | I9: 450 | J9: 94 | K9: 18329466 | L9: 18000000 | M9: =VLOOKUP(A9,Sheet2!$A$1:G3733,2,0) -> 40312 | N9: =VLOOKUP(A9,Sheet2!$A$1:G3733,3,0) -> Color | O9: =VLOOKUP(A9,Sheet2!$A$1:G3733,4,0) -> Adventure | P9: =VLOOKUP(A9,Sheet2!$A$1:G3733,5,0) -> English | Q9: =VLOOKUP(A9,Sheet2!$A$1:G3733,6,0) -> USA | R9: =VLOOKUP(A9,Sheet2!$A$1:G3733,7,0) -> R | S9: =IF(Table1[[#This Row],[Language]]="English","English","Other language") -> English | T9: =Table1[[#This Row],[Gross Revenue]]-Table1[[#This Row],[Budget]] -> 329466 | U9: =(Table1[[#This Row],[Gross Revenue]]/Table1[[#This Row],[Budget]])-1 -> 0.018303667 | V9: =IF(J9="","",IF(J9<90,"<90 minutes",IF(J9<=110,"90-110 minutes",IF(J9<=130,"111-130 minutes",IF(J9<=150,"131-150 minutes",">150 minutes"))))) -> 90-110 minutes | W9: =Table1[[#This Row],[Profit]]/Table1[[#This Row],[Budget]] -> 0.018303667 | X9: =IF(L9="","", IF(L9<Predictability!$B$1,"Low", IF(L9<=Predictability!$B$2,"Mid","High"))) -> Mid | Y9: =IF(W9>=0.5,1,0) -> 0
A10: 13 Going on 30 | B10: Jennifer Garner | C10: Gary Winick | D10: 3000 | E10: 6742 | F10: 56 | G10: 0 | H10: 6.1 | I10: 119 | J10: 98 | K10: 56044241 | L10: 37000000 | M10: =VLOOKUP(A10,Sheet2!$A$1:G3734,2,0) -> 38154 | N10: =VLOOKUP(A10,Sheet2!$A$1:G3734,3,0) -> Color | O10: =VLOOKUP(A10,Sheet2!$A$1:G3734,4,0) -> Comedy | P10: =VLOOKUP(A10,Sheet2!$A$1:G3734,5,0) -> English | Q10: =VLOOKUP(A10,Sheet2!$A$1:G3734,6,0) -> USA | R10: =VLOOKUP(A10,Sheet2!$A$1:G3734,7,0) -> PG-13 | S10: =IF(Table1[[#This Row],[Language]]="English","English","Other language") -> English | T10: =Table1[[#This Row],[Gross Revenue]]-Table1[[#This Row],[Budget]] -> 19044241 | U10: =(Table1[[#This Row],[Gross Revenue]]/Table1[[#This Row],[Budget]])-1 -> 0.51470922 | V10: =IF(J10="","",IF(J10<90,"<90 minutes",IF(J10<=110,"90-110 minutes",IF(J10<=130,"111-130 minutes",IF(J10<=150,"131-150 minutes",">150 minutes"))))) -> 90-110 minutes | W10: =Table1[[#This Row],[Profit]]/Table1[[#This Row],[Budget]] -> 0.51470922 | X10: =IF(L10="","", IF(L10<Predictability!$B$1,"Low", IF(L10<=Predictability!$B$2,"Mid","High"))) -> Mid | Y10: =IF(W10>=0.5,1,0) -> 1
A11: 1408 | B11: Drew Powell | C11: Mikael HÃ¥fstrÃ¶m | D11: 129 | E11: 214 | F11: 101 | G11: 11000 | H11: 6.8 | I11: 314 | J11: 114 | K11: 71975611 | L11: 25000000 | M11: =VLOOKUP(A11,Sheet2!$A$1:G3735,2,0) -> 39152 | N11: =VLOOKUP(A11,Sheet2!$A$1:G3735,3,0) -> Color | O11: =VLOOKUP(A11,Sheet2!$A$1:G3735,4,0) -> Fantasy | P11: =VLOOKUP(A11,Sheet2!$A$1:G3735,5,0) -> English | Q11: =VLOOKUP(A11,Sheet2!$A$1:G3735,6,0) -> USA | R11: =VLOOKUP(A11,Sheet2!$A$1:G3735,7,0) -> PG-13 | S11: =IF(Table1[[#This Row],[Language]]="English","English","Other language") -> English | T11: =Table1[[#This Row],[Gross Revenue]]-Table1[[#This Row],[Budget]] -> 46975611 | U11: =(Table1[[#This Row],[Gross Revenue]]/Table1[[#This Row],[Budget]])-1 -> 1.8790244 | V11: =IF(J11="","",IF(J11<90,"<90 minutes",IF(J11<=110,"90-110 minutes",IF(J11<=130,"111-130 minutes",IF(J11<=150,"131-150 minutes",">150 minutes"))))) -> 111-130 minutes | W11: =Table1[[#This Row],[Profit]]/Table1[[#This Row],[Budget]] -> 1.8790244 | X11: =IF(L11="","", IF(L11<Predictability!$B$1,"Low", IF(L11<=Predictability!$B$2,"Mid","High"))) -> Mid | Y11: =IF(W11>=0.5,1,0) -> 1
A12: 15 Minutes | B12: Robert De Niro | C12: John Herzfeld | D12: 22000 | E12: 33585 | F12: 17 | G12: 748 | H12: 6.1 | I12: 151 | J12: 120 | K12: 24375436 | L12: 42000000 | M12: =VLOOKUP(A12,Sheet2!$A$1:G3736,2,0) -> 36908 | N12: =VLOOKUP(A12,Sheet2!$A$1:G3736,3,0) -> Color | O12: =VLOOKUP(A12,Sheet2!$A$1:G3736,4,0) -> Action | P12: =VLOOKUP(A12,Sheet2!$A$1:G3736,5,0) -> English | Q12: =VLOOKUP(A12,Sheet2!$A$1:G3736,6,0) -> USA | R12: =VLOOKUP(A12,Sheet2!$A$1:G3736,7,0) -> R | S12: =IF(Table1[[#This Row],[Language]]="English","English","Other language") -> English | T12: =Table1[[#This Row],[Gross Revenue]]-Table1[[#This Row],[Budget]] -> -17624564 | U12: =(Table1[[#This Row],[Gross Revenue]]/Table1[[#This Row],[Budget]])-1 -> -0.41963248 | V12: =IF(J12="","",IF(J12<90,"<90 minutes",IF(J12<=110,"90-110 minutes",IF(J12<=130,"111-130 minutes",IF(J12<=150,"131-150 minutes",">150 minutes"))))) -> 111-130 minutes | W12: =Table1[[#This Row],[Profit]]/Table1[[#This Row],[Budget]] -> -0.41963248 | X12: =IF(L12="","", IF(L12<Predictability!$B$1,"Low", IF(L12<=Predictability!$B$2,"Mid","High"))) -> Mid | Y12: =IF(W12>=0.5,1,0) -> 0
A13: 16 Blocks | B13: Bruce Willis | C13: Richard Donner | D13: 13000 | E13: 15053 | F13: 503 | G13: 0 | H13: 6.6 | I13: 199 | J13: 102 | K13: 36883539 | L13: 52000000 | M13: =VLOOKUP(A13,Sheet2!$A$1:G3737,2,0) -> 39029 | N13: =VLOOKUP(A13,Sheet2!$A$1:G3737,3,0) -> Color | O13: =VLOOKUP(A13,Sheet2!$A$1:G3737,4,0) -> Action | P13: =VLOOKUP(A13,Sheet2!$A$1:G3737,5,0) -> English | Q13: =VLOOKUP(A13,Sheet2!$A$1:G3737,6,0) -> Germany | R13: =VLOOKUP(A13,Sheet2!$A$1:G3737,7,0) -> PG-13 | S13: =IF(Table1[[#This Row],[Language]]="English","English","Other language") -> English | T13: =Table1[[#This Row],[Gross Revenue]]-Table1[[#This Row],[Budget]] -> -15116461 | U13: =(Table1[[#This Row],[Gross Revenue]]/Table1[[#This Row],[Budget]])-1 -> -0.29070117 | V13: =IF(J13="","",IF(J13<90,"<90 minutes",IF(J13<=110,"90-110 minutes",IF(J13<=130,"111-130 minutes",IF(J13<=150,"131-150 minutes",">150 minutes"))))) -> 90-110 minutes | W13: =Table1[[#This Row],[Profit]]/Table1[[#This Row],[Budget]] -> -0.29070117 | X13: =IF(L13="","", IF(L13<Predictability!$B$1,"Low", IF(L13<=Predictability!$B$2,"Mid","High"))) -> High | Y13: =IF(W13>=0.5,1,0) -> 0
A14: 17 Again | B14: Matthew Perry | C14: Burr Steers | D14: 2000 | E14: 7009 | F14: 23 | G14: 0 | H14: 6.4 | I14: 191 | J14: 102 | K14: 64149837 | L14: 20000000 | M14: =VLOOKUP(A14,Sheet2!$A$1:G3738,2,0) -> 39958 | N14: =VLOOKUP(A14,Sheet2!$A$1:G3738,3,0) -> Color | O14: =VLOOKUP(A14,Sheet2!$A$1:G3738,4,0) -> Comedy | P14: =VLOOKUP(A14,Sheet2!$A$1:G3738,5,0) -> English | Q14: =VLOOKUP(A14,Sheet2!$A$1:G3738,6,0) -> USA | R14: =VLOOKUP(A14,Sheet2!$A$1:G3738,7,0) -> PG-13 | S14: =IF(Table1[[#This Row],[Language]]="English","English","Other language") -> English | T14: =Table1[[#This Row],[Gross Revenue]]-Table1[[#This Row],[Budget]] -> 44149837 | U14: =(Table1[[#This Row],[Gross Revenue]]/Table1[[#This Row],[Budget]])-1 -> 2.2074918 | V14: =IF(J14="","",IF(J14<90,"<90 minutes",IF(J14<=110,"90-110 minutes",IF(J14<=130,"111-130 minutes",IF(J14<=150,"131-150 minutes",">150 minutes"))))) -> 90-110 minutes | W14: =Table1[[#This Row],[Profit]]/Table1[[#This Row],[Budget]] -> 2.2074918 | X14: =IF(L14="","", IF(L14<Predictability!$B$1,"Low", IF(L14<=Predictability!$B$2,"Mid","High"))) -> Mid | Y14: =IF(W14>=0.5,1,0) -> 1
... A268: Army of Darkness | B268: Patricia Tallman | C268: Sam Raimi | D268: 901 | E268: 3913 | F268: 0 | G268: 10000 | H268: 7.6 | I268: 221 | J268: 88 | K268: 11501093 | L268: 13000000 | M268: =VLOOKUP(A268,Sheet2!$A$1:G3992,2,0) -> 33605 | N268: =VLOOKUP(A268,Sheet2!$A$1:G3992,3,0) -> Color | O268: =VLOOKUP(A268,Sheet2!$A$1:G3992,4,0) -> Comedy | P268: =VLOOKUP(A268,Sheet2!$A$1:G3992,5,0) -> English | Q268: =VLOOKUP(A268,Sheet2!$A$1:G3992,6,0) -> USA | R268: =VLOOKUP(A268,Sheet2!$A$1:G3992,7,0) -> R | S268: =IF(Table1[[#This Row],[Language]]="English","English","Other language") -> English | T268: =Table1[[#This Row],[Gross Revenue]]-Table1[[#This Row],[Budget]] -> -1498907 | U268: =(Table1[[#This Row],[Gross Revenue]]/Table1[[#This Row],[Budget]])-1 -> -0.11530054 | V268: =IF(J268="","",IF(J268<90,"<90 minutes",IF(J268<=110,"90-110 minutes",IF(J268<=130,"111-130 minutes",IF(J268<=150,"131-150 minutes",">150 minutes"))))) -> <90 minutes | W268: =Table1[[#This Row],[Profit]]/Table1[[#This Row],[Budget]] -> -0.11530054 | X268: =IF(L268="","", IF(L268<Predictability!$B$1,"Low", IF(L268<=Predictability!$B$2,"Mid","High"))) -> Mid | Y268: =IF(W268>=0.5,1,0) -> 0
A269: Arnolds Park | B269: Kendyl Joi | C269: Gene Teigland | D269: 23 | E269: 85 | F269: 0 | G269: 11 | H269: 5.6 | J269: 103 | K269: 23616 | L269: 600000 | M269: =VLOOKUP(A269,Sheet2!$A$1:G3993,2,0) -> 39322 | N269: =VLOOKUP(A269,Sheet2!$A$1:G3993,3,0) -> Color | O269: =VLOOKUP(A269,Sheet2!$A$1:G3993,4,0) -> Mystery | P269: =VLOOKUP(A269,Sheet2!$A$1:G3993,5,0) -> English | Q269: =VLOOKUP(A269,Sheet2!$A$1:G3993,6,0) -> USA | R269: =VLOOKUP(A269,Sheet2!$A$1:G3993,7,0) -> PG-13 | S269: =IF(Table1[[#This Row],[Language]]="English","English","Other language") -> English | T269: =Table1[[#This Row],[Gross Revenue]]-Table1[[#This Row],[Budget]] -> -576384 | U269: =(Table1[[#This Row],[Gross Revenue]]/Table1[[#This Row],[Budget]])-1 -> -0.96064 | V269: =IF(J269="","",IF(J269<90,"<90 minutes",IF(J269<=110,"90-110 minutes",IF(J269<=130,"111-130 minutes",IF(J269<=150,"131-150 minutes",">150 minutes"))))) -> 90-110 minutes | W269: =Table1[[#This Row],[Profit]]/Table1[[#This Row],[Budget]] -> -0.96064 | X269: =IF(L269="","", IF(L269<Predictability!$B$1,"Low", IF(L269<=Predictability!$B$2,"Mid","High"))) -> Low | Y269: =IF(W269>=0.5,1,0) -> 0
A270: Around the World in 80 Days | B270: Jim Broadbent | C270: Frank Coraci | D270: 1000 | E270: 3175 | F270: 153 | G270: 0 | H270: 5.8 | I270: 188 | J270: 120 | K270: 24004159 | L270: 110000000 | M270: =VLOOKUP(A270,Sheet2!$A$1:G3994,2,0) -> 38020 | N270: =VLOOKUP(A270,Sheet2!$A$1:G3994,3,0) -> Color | O270: =VLOOKUP(A270,Sheet2!$A$1:G3994,4,0) -> Action | P270: =VLOOKUP(A270,Sheet2!$A$1:G3994,5,0) -> English | Q270: =VLOOKUP(A270,Sheet2!$A$1:G3994,6,0) -> USA | R270: =VLOOKUP(A270,Sheet2!$A$1:G3994,7,0) -> PG | S270: =IF(Table1[[#This Row],[Language]]="English","English","Other language") -> English | T270: =Table1[[#This Row],[Gross Revenue]]-Table1[[#This Row],[Budget]] -> -85995841 | U270: =(Table1[[#This Row],[Gross Revenue]]/Table1[[#This Row],[Budget]])-1 -> -0.78178037 | V270: =IF(J270="","",IF(J270<90,"<90 minutes",IF(J270<=110,"90-110 minutes",IF(J270<=130,"111-130 minutes",IF(J270<=150,"131-150 minutes",">150 minutes"))))) -> 111-130 minutes | W270: =Table1[[#This Row],[Profit]]/Table1[[#This Row],[Budget]] -> -0.78178037 | X270: =IF(L270="","", IF(L270<Predictability!$B$1,"Low", IF(L270<=Predictability!$B$2,"Mid","High"))) -> High | Y270: =IF(W270>=0.5,1,0) -> 0
A271: Arthur and the Invisibles | B271: Mia Farrow | C271: Luc Besson | D271: 563 | E271: 683 | F271: 0 | G271: 941 | H271: 6 | I271: 101 | J271: 94 | K271: 15131330 | L271: 86000000 | M271: =VLOOKUP(A271,Sheet2!$A$1:G3995,2,0) -> 39041 | N271: =VLOOKUP(A271,Sheet2!$A$1:G3995,3,0) -> Color | O271: =VLOOKUP(A271,Sheet2!$A$1:G3995,4,0) -> Adventure | P271: =VLOOKUP(A271,Sheet2!$A$1:G3995,5,0) -> English | Q271: =VLOOKUP(A271,Sheet2!$A$1:G3995,6,0) -> France | R271: =VLOOKUP(A271,Sheet2!$A$1:G3995,7,0) -> PG | S271: =IF(Table1[[#This Row],[Language]]="English","English","Other language") -> English | T271: =Table1[[#This Row],[Gross Revenue]]-Table1[[#This Row],[Budget]] -> -70868670 | U271: =(Table1[[#This Row],[Gross Revenue]]/Table1[[#This Row],[Budget]])-1 -> -0.8240543 | V271: =IF(J271="","",IF(J271<90,"<90 minutes",IF(J271<=110,"90-110 minutes",IF(J271<=130,"111-130 minutes",IF(J271<=150,"131-150 minutes",">150 minutes"))))) -> 90-110 minutes | W271: =Table1[[#This Row],[Profit]]/Table1[[#This Row],[Budget]] -> -0.8240543 | X271: =IF(L271="","", IF(L271<Predictability!$B$1,"Low", IF(L271<=Predictability!$B$2,"Mid","High"))) -> High | Y271: =IF(W271>=0.5,1,0) -> 0
A272: Arthur Christmas | B272: Jim Broadbent | C272: Sarah Smith | D272: 1000 | E272: 2707 | F272: 6 | G272: 0 | H272: 7.1 | I272: 190 | J272: 97 | K272: 46440491 | L272: 100000000 | M272: =VLOOKUP(A272,Sheet2!$A$1:G3996,2,0) -> 40761 | N272: =VLOOKUP(A272,Sheet2!$A$1:G3996,3,0) -> Color | O272: =VLOOKUP(A272,Sheet2!$A$1:G3996,4,0) -> Adventure | P272: =VLOOKUP(A272,Sheet2!$A$1:G3996,5,0) -> English | Q272: =VLOOKUP(A272,Sheet2!$A$1:G3996,6,0) -> UK | R272: =VLOOKUP(A272,Sheet2!$A$1:G3996,7,0) -> PG | S272: =IF(Table1[[#This Row],[Language]]="English","English","Other language") -> English | T272: =Table1[[#This Row],[Gross Revenue]]-Table1[[#This Row],[Budget]] -> -53559509 | U272: =(Table1[[#This Row],[Gross Revenue]]/Table1[[#This Row],[Budget]])-1 -> -0.53559509 | V272: =IF(J272="","",IF(J272<90,"<90 minutes",IF(J272<=110,"90-110 minutes",IF(J272<=130,"111-130 minutes",IF(J272<=150,"131-150 minutes",">150 minutes"))))) -> 90-110 minutes | W272: =Table1[[#This Row],[Profit]]/Table1[[#This Row],[Budget]] -> -0.53559509 | X272: =IF(L272="","", IF(L272<Predictability!$B$1,"Low", IF(L272<=Predictability!$B$2,"Mid","High"))) -> High | Y272: =IF(W272>=0.5,1,0) -> 0
A273: As Above, So Below | B273: Ben Feldman | C273: John Erick Dowdle | D273: 1000 | E273: 1410 | F273: 66 | G273: 14000 | H273: 6.1 | I273: 196 | J273: 93 | K273: 21197315 | L273: 5000000 | M273: =VLOOKUP(A273,Sheet2!$A$1:G3997,2,0) -> 41977 | N273: =VLOOKUP(A273,Sheet2!$A$1:G3997,3,0) -> Color | O273: =VLOOKUP(A273,Sheet2!$A$1:G3997,4,0) -> Horror | P273: =VLOOKUP(A273,Sheet2!$A$1:G3997,5,0) -> English | Q273: =VLOOKUP(A273,Sheet2!$A$1:G3997,6,0) -> USA | R273: =VLOOKUP(A273,Sheet2!$A$1:G3997,7,0) -> R | S273: =IF(Table1[[#This Row],[Language]]="English","English","Other language") -> English | T273: =Table1[[#This Row],[Gross Revenue]]-Table1[[#This Row],[Budget]] -> 16197315 | U273: =(Table1[[#This Row],[Gross Revenue]]/Table1[[#This Row],[Budget]])-1 -> 3.239463 | V273: =IF(J273="","",IF(J273<90,"<90 minutes",IF(J273<=110,"90-110 minutes",IF(J273<=130,"111-130 minutes",IF(J273<=150,"131-150 minutes",">150 minutes"))))) -> 90-110 minutes | W273: =Table1[[#This Row],[Profit]]/Table1[[#This Row],[Budget]] -> 3.239463 | X273: =IF(L273="","", IF(L273<Predictability!$B$1,"Low", IF(L273<=Predictability!$B$2,"Mid","High"))) -> Low | Y273: =IF(W273>=0.5,1,0) -> 1
A274: As Good as It Gets | B274: Lupe Ontiveros | C274: James L. Brooks | D274: 625 | E274: 1474 | F274: 274 | G274: 11000 | H274: 7.7 | I274: 156 | J274: 139 | K274: 147637474 | L274: 50000000 | M274: =VLOOKUP(A274,Sheet2!$A$1:G3998,2,0) -> 35778 | N274: =VLOOKUP(A274,Sheet2!$A$1:G3998,3,0) -> Color | O274: =VLOOKUP(A274,Sheet2!$A$1:G3998,4,0) -> Comedy | P274: =VLOOKUP(A274,Sheet2!$A$1:G3998,5,0) -> English | Q274: =VLOOKUP(A274,Sheet2!$A$1:G3998,6,0) -> USA | R274: =VLOOKUP(A274,Sheet2!$A$1:G3998,7,0) -> PG-13 | S274: =IF(Table1[[#This Row],[Language]]="English","English","Other language") -> English | T274: =Table1[[#This Row],[Gross Revenue]]-Table1[[#This Row],[Budget]] -> 97637474 | U274: =(Table1[[#This Row],[Gross Revenue]]/Table1[[#This Row],[Budget]])-1 -> 1.9527495 | V274: =IF(J274="","",IF(J274<90,"<90 minutes",IF(J274<=110,"90-110 minutes",IF(J274<=130,"111-130 minutes",IF(J274<=150,"131-150 minutes",">150 minutes"))))) -> 131-150 minutes | W274: =Table1[[#This Row],[Profit]]/Table1[[#This Row],[Budget]] -> 1.9527495 | X274: =IF(L274="","", IF(L274<Predictability!$B$1,"Low", IF(L274<=Predictability!$B$2,"Mid","High"))) -> Mid | Y274: =IF(W274>=0.5,1,0) -> 1
A275: As It Is in Heaven | B275: Michael Nyqvist | C275: Kay Pollak | D275: 690 | E275: 774 | F275: 10 | G275: 0 | H275: 7.6 | I275: 34 | J275: 133 | K275: 9910 | L275: 25000000 | M275: =VLOOKUP(A275,Sheet2!$A$1:G3999,2,0) -> 38117 | N275: =VLOOKUP(A275,Sheet2!$A$1:G3999,3,0) -> Color | O275: =VLOOKUP(A275,Sheet2!$A$1:G3999,4,0) -> Comedy | P275: =VLOOKUP(A275,Sheet2!$A$1:G3999,5,0) -> Swedish | Q275: =VLOOKUP(A275,Sheet2!$A$1:G3999,6,0) -> Sweden | R275: =VLOOKUP(A275,Sheet2!$A$1:G3999,7,0) -> 0 | S275: =IF(Table1[[#This Row],[Language]]="English","English","Other language") -> Other language | T275: =Table1[[#This Row],[Gross Revenue]]-Table1[[#This Row],[Budget]] -> -24990090 | U275: =(Table1[[#This Row],[Gross Revenue]]/Table1[[#This Row],[Budget]])-1 -> -0.9996036 | V275: =IF(J275="","",IF(J275<90,"<90 minutes",IF(J275<=110,"90-110 minutes",IF(J275<=130,"111-130 minutes",IF(J275<=150,"131-150 minutes",">150 minutes"))))) -> 131-150 minutes | W275: =Table1[[#This Row],[Profit]]/Table1[[#This Row],[Budget]] -> -0.9996036 | X275: =IF(L275="","", IF(L275<Predictability!$B$1,"Low", IF(L275<=Predictability!$B$2,"Mid","High"))) -> Mid | Y275: =IF(W275>=0.5,1,0) -> 0
A276: Assassins | B276: Muse Watson | C276: Richard Donner | D276: 45000 | E276: 58528 | F276: 503 | G276: 0 | H276: 6.3 | I276: 61 | J276: 132 | K276: 30306268 | L276: 50000000 | M276: =VLOOKUP(A276,Sheet2!$A$1:G4000,2,0) -> 34751 | N276: =VLOOKUP(A276,Sheet2!$A$1:G4000,3,0) -> Black and White | O276: =VLOOKUP(A276,Sheet2!$A$1:G4000,4,0) -> Action | P276: =VLOOKUP(A276,Sheet2!$A$1:G4000,5,0) -> English | Q276: =VLOOKUP(A276,Sheet2!$A$1:G4000,6,0) -> France | R276: =VLOOKUP(A276,Sheet2!$A$1:G4000,7,0) -> R | S276: =IF(Table1[[#This Row],[Language]]="English","English","Other language") -> English | T276: =Table1[[#This Row],[Gross Revenue]]-Table1[[#This Row],[Budget]] -> -19693732 | U276: =(Table1[[#This Row],[Gross Revenue]]/Table1[[#This Row],[Budget]])-1 -> -0.39387464 | V276: =IF(J276="","",IF(J276<90,"<90 minutes",IF(J276<=110,"90-110 minutes",IF(J276<=130,"111-130 minutes",IF(J276<=150,"131-150 minutes",">150 minutes"))))) -> 131-150 minutes | W276: =Table1[[#This Row],[Profit]]/Table1[[#This Row],[Budget]] -> -0.39387464 | X276: =IF(L276="","", IF(L276<Predictability!$B$1,"Low", IF(L276<=Predictability!$B$2,"Mid","High"))) -> Mid | Y276: =IF(W276>=0.5,1,0) -> 0
A277: Assault on Precinct 13 | B277: Brian Dennehy | C277: Jean-FranÃ§ois Richet | D277: 954 | E277: 3148 | F277: 25 | G277: 999 | H277: 6.3 | I277: 152 | J277: 109 | K277: 19976073 | L277: 20000000 | M277: =VLOOKUP(A277,Sheet2!$A$1:G4001,2,0) -> 38390 | N277: =VLOOKUP(A277,Sheet2!$A$1:G4001,3,0) -> Color | O277: =VLOOKUP(A277,Sheet2!$A$1:G4001,4,0) -> Action | P277: =VLOOKUP(A277,Sheet2!$A$1:G4001,5,0) -> English | Q277: =VLOOKUP(A277,Sheet2!$A$1:G4001,6,0) -> USA | R277: =VLOOKUP(A277,Sheet2!$A$1:G4001,7,0) -> R | S277: =IF(Table1[[#This Row],[Language]]="English","English","Other language") -> English | T277: =Table1[[#This Row],[Gross Revenue]]-Table1[[#This Row],[Budget]] -> -23927 | U277: =(Table1[[#This Row],[Gross Revenue]]/Table1[[#This Row],[Budget]])-1 -> -0.00119635 | V277: =IF(J277="","",IF(J277<90,"<90 minutes",IF(J277<=110,"90-110 minutes",IF(J277<=130,"111-130 minutes",IF(J277<=150,"131-150 minutes",">150 minutes"))))) -> 90-110 minutes | W277: =Table1[[#This Row],[Profit]]/Table1[[#This Row],[Budget]] -> -0.00119635 | X277: =IF(L277="","", IF(L277<Predictability!$B$1,"Low", IF(L277<=Predictability!$B$2,"Mid","High"))) -> Mid | Y277: =IF(W277>=0.5,1,0) -> 0
A278: Astro Boy | B278: Nicolas Cage | C278: David Bowers | D278: 12000 | E278: 23365 | F278: 42 | G278: 0 | H278: 6.3 | I278: 138 | J278: 94 | K278: 19548064 | L278: 65000000 | M278: =VLOOKUP(A278,Sheet2!$A$1:G4002,2,0) -> 39881 | N278: =VLOOKUP(A278,Sheet2!$A$1:G4002,3,0) -> Color | O278: =VLOOKUP(A278,Sheet2!$A$1:G4002,4,0) -> Action | P278: =VLOOKUP(A278,Sheet2!$A$1:G4002,5,0) -> English | Q278: =VLOOKUP(A278,Sheet2!$A$1:G4002,6,0) -> Hong Kong | R278: =VLOOKUP(A278,Sheet2!$A$1:G4002,7,0) -> PG | S278: =IF(Table1[[#This Row],[Language]]="English","English","Other language") -> English | T278: =Table1[[#This Row],[Gross Revenue]]-Table1[[#This Row],[Budget]] -> -45451936 | U278: =(Table1[[#This Row],[Gross Revenue]]/Table1[[#This Row],[Budget]])-1 -> -0.69926055 | V278: =IF(J278="","",IF(J278<90,"<90 minutes",IF(J278<=110,"90-110 minutes",IF(J278<=130,"111-130 minutes",IF(J278<=150,"131-150 minutes",">150 minutes"))))) -> 90-110 minutes | W278: =Table1[[#This Row],[Profit]]/Table1[[#This Row],[Budget]] -> -0.69926055 | X278: =IF(L278="","", IF(L278<Predictability!$B$1,"Low", IF(L278<=Predictability!$B$2,"Mid","High"))) -> High | Y278: =IF(W278>=0.5,1,0) -> 0
A279: At First Sight | B279: Mira Sorvino | C279: Irwin Winkler | D279: 978 | E279: 3821 | F279: 34 | G279: 0 | H279: 5.9 | I279: 55 | J279: 128 | K279: 22326247 | L279: 60000000 | M279: =VLOOKUP(A279,Sheet2!$A$1:G4003,2,0) -> 36284 | N279: =VLOOKUP(A279,Sheet2!$A$1:G4003,3,0) -> Black and White | O279: =VLOOKUP(A279,Sheet2!$A$1:G4003,4,0) -> Drama | P279: =VLOOKUP(A279,Sheet2!$A$1:G4003,5,0) -> English | Q279: =VLOOKUP(A279,Sheet2!$A$1:G4003,6,0) -> USA | R279: =VLOOKUP(A279,Sheet2!$A$1:G4003,7,0) -> PG-13 | S279: =IF(Table1[[#This Row],[Language]]="English","English","Other language") -> English | T279: =Table1[[#This Row],[Gross Revenue]]-Table1[[#This Row],[Budget]] -> -37673753 | U279: =(Table1[[#This Row],[Gross Revenue]]/Table1[[#This Row],[Budget]])-1 -> -0.62789588 | V279: =IF(J279="","",IF(J279<90,"<90 minutes",IF(J279<=110,"90-110 minutes",IF(J279<=130,"111-130 minutes",IF(J279<=150,"131-150 minutes",">150 minutes"))))) -> 111-130 minutes | W279: =Table1[[#This Row],[Profit]]/Table1[[#This Row],[Budget]] -> -0.62789588 | X279: =IF(L279="","", IF(L279<Predictability!$B$1,"Low", IF(L279<=Predictability!$B$2,"Mid","High"))) -> High | Y279: =IF(W279>=0.5,1,0) -> 0
A280: Atlantis: The Lost Empire | B280: Leonard Nimoy | C280: Gary Trousdale | D280: 12000 | E280: 15237 | F280: 21 | G280: 0 | H280: 6.8 | I280: 146 | J280: 95 | K280: 84037039 | L280: 120000000 | M280: =VLOOKUP(A280,Sheet2!$A$1:G4004,2,0) -> 37085 | N280: =VLOOKUP(A280,Sheet2!$A$1:G4004,3,0) -> Color | O280: =VLOOKUP(A280,Sheet2!$A$1:G4004,4,0) -> Action | P280: =VLOOKUP(A280,Sheet2!$A$1:G4004,5,0) -> English | Q280: =VLOOKUP(A280,Sheet2!$A$1:G4004,6,0) -> USA | R280: =VLOOKUP(A280,Sheet2!$A$1:G4004,7,0) -> PG | S280: =IF(Table1[[#This Row],[Language]]="English","English","Other language") -> English | T280: =Table1[[#This Row],[Gross Revenue]]-Table1[[#This Row],[Budget]] -> -35962961 | U280: =(Table1[[#This Row],[Gross Revenue]]/Table1[[#This Row],[Budget]])-1 -> -0.29969134 | V280: =IF(J280="","",IF(J280<90,"<90 minutes",IF(J280<=110,"90-110 minutes",IF(J280<=130,"111-130 minutes",IF(J280<=150,"131-150 minutes",">150 minutes"))))) -> 90-110 minutes | W280: =Table1[[#This Row],[Profit]]/Table1[[#This Row],[Budget]] -> -0.29969134 | X280: =IF(L280="","", IF(L280<Predictability!$B$1,"Low", IF(L280<=Predictability!$B$2,"Mid","High"))) -> High | Y280: =IF(W280>=0.5,1,0) -> 0
A281: Atlas Shrugged II: The Strike | B281: Robert Picardo | C281: John Putch | D281: 823 | E281: 5262 | F281: 60 | G281: 0 | H281: 5.5 | I281: 23 | J281: 111 | K281: 3333823 | L281: 10000000 | M281: =VLOOKUP(A281,Sheet2!$A$1:G4005,2,0) -> 41026 | N281: =VLOOKUP(A281,Sheet2!$A$1:G4005,3,0) -> Color | O281: =VLOOKUP(A281,Sheet2!$A$1:G4005,4,0) -> Drama | P281: =VLOOKUP(A281,Sheet2!$A$1:G4005,5,0) -> English | Q281: =VLOOKUP(A281,Sheet2!$A$1:G4005,6,0) -> USA | R281: =VLOOKUP(A281,Sheet2!$A$1:G4005,7,0) -> PG-13 | S281: =IF(Table1[[#This Row],[Language]]="English","English","Other language") -> English | T281: =Table1[[#This Row],[Gross Revenue]]-Table1[[#This Row],[Budget]] -> -6666177 | U281: =(Table1[[#This Row],[Gross Revenue]]/Table1[[#This Row],[Budget]])-1 -> -0.6666177 | V281: =IF(J281="","",IF(J281<90,"<90 minutes",IF(J281<=110,"90-110 minutes",IF(J281<=130,"111-130 minutes",IF(J281<=150,"131-150 minutes",">150 minutes"))))) -> 111-130 minutes | W281: =Table1[[#This Row],[Profit]]/Table1[[#This Row],[Budget]] -> -0.6666177 | X281: =IF(L281="","", IF(L281<Predictability!$B$1,"Low", IF(L281<=Predictability!$B$2,"Mid","High"))) -> Mid | Y281: =IF(W281>=0.5,1,0) -> 0
... A297: Away We Go | B297: Catherine O'Hara | C297: Sam Mendes | D297: 925 | E297: 1997 | F297: 0 | G297: 7000 | H297: 7.1 | I297: 217 | J297: 98 | K297: 9430988 | L297: 17000000 | M297: =VLOOKUP(A297,Sheet2!$A$1:G4021,2,0) -> 40118 | N297: =VLOOKUP(A297,Sheet2!$A$1:G4021,3,0) -> Color | O297: =VLOOKUP(A297,Sheet2!$A$1:G4021,4,0) -> Comedy | P297: =VLOOKUP(A297,Sheet2!$A$1:G4021,5,0) -> English | Q297: =VLOOKUP(A297,Sheet2!$A$1:G4021,6,0) -> USA | R297: =VLOOKUP(A297,Sheet2!$A$1:G4021,7,0) -> R | S297: =IF(Table1[[#This Row],[Language]]="English","English","Other language") -> English | T297: =Table1[[#This Row],[Gross Revenue]]-Table1[[#This Row],[Budget]] -> -7569012 | U297: =(Table1[[#This Row],[Gross Revenue]]/Table1[[#This Row],[Budget]])-1 -> -0.445236 | V297: =IF(J297="","",IF(J297<90,"<90 minutes",IF(J297<=110,"90-110 minutes",IF(J297<=130,"111-130 minutes",IF(J297<=150,"131-150 minutes",">150 minutes"))))) -> 90-110 minutes | W297: =Table1[[#This Row],[Profit]]/Table1[[#This Row],[Budget]] -> -0.445236 | X297: =IF(L297="","", IF(L297<Predictability!$B$1,"Low", IF(L297<=Predictability!$B$2,"Mid","High"))) -> Mid | Y297: =IF(W297>=0.5,1,0) -> 0
A298: Ayurveda: Art of Being | C298: Pan Nalin | E298: 0 | F298: 95 | G298: 379 | H298: 7.6 | I298: 15 | J298: 102 | K298: 16892 | L298: 300000 | M298: =VLOOKUP(A298,Sheet2!$A$1:G4022,2,0) -> 37138 | N298: =VLOOKUP(A298,Sheet2!$A$1:G4022,3,0) -> Color | O298: =VLOOKUP(A298,Sheet2!$A$1:G4022,4,0) -> Documentary | P298: =VLOOKUP(A298,Sheet2!$A$1:G4022,5,0) -> English | Q298: =VLOOKUP(A298,Sheet2!$A$1:G4022,6,0) -> India | R298: =VLOOKUP(A298,Sheet2!$A$1:G4022,7,0) -> 0 | S298: =IF(Table1[[#This Row],[Language]]="English","English","Other language") -> English | T298: =Table1[[#This Row],[Gross Revenue]]-Table1[[#This Row],[Budget]] -> -283108 | U298: =(Table1[[#This Row],[Gross Revenue]]/Table1[[#This Row],[Budget]])-1 -> -0.94369333 | V298: =IF(J298="","",IF(J298<90,"<90 minutes",IF(J298<=110,"90-110 minutes",IF(J298<=130,"111-130 minutes",IF(J298<=150,"131-150 minutes",">150 minutes"))))) -> 90-110 minutes | W298: =Table1[[#This Row],[Profit]]/Table1[[#This Row],[Budget]] -> -0.94369333 | X298: =IF(L298="","", IF(L298<Predictability!$B$1,"Low", IF(L298<=Predictability!$B$2,"Mid","High"))) -> Low | Y298: =IF(W298>=0.5,1,0) -> 0
A299: Baahubali: The Beginning | B299: Tamannaah Bhatia | C299: S.S. Rajamouli | D299: 218 | E299: 554 | F299: 50 | G299: 21000 | H299: 8.4 | I299: 44 | J299: 159 | K299: 6498000 | L299: 18026148 | M299: =VLOOKUP(A299,Sheet2!$A$1:G4023,2,0) -> 42182 | N299: =VLOOKUP(A299,Sheet2!$A$1:G4023,3,0) -> Color | O299: =VLOOKUP(A299,Sheet2!$A$1:G4023,4,0) -> Action | P299: =VLOOKUP(A299,Sheet2!$A$1:G4023,5,0) -> Telugu | Q299: =VLOOKUP(A299,Sheet2!$A$1:G4023,6,0) -> India | R299: =VLOOKUP(A299,Sheet2!$A$1:G4023,7,0) -> 0 | S299: =IF(Table1[[#This Row],[Language]]="English","English","Other language") -> Other language | T299: =Table1[[#This Row],[Gross Revenue]]-Table1[[#This Row],[Budget]] -> -11528148 | U299: =(Table1[[#This Row],[Gross Revenue]]/Table1[[#This Row],[Budget]])-1 -> -0.63952365 | V299: =IF(J299="","",IF(J299<90,"<90 minutes",IF(J299<=110,"90-110 minutes",IF(J299<=130,"111-130 minutes",IF(J299<=150,"131-150 minutes",">150 minutes"))))) -> >150 minutes | W299: =Table1[[#This Row],[Profit]]/Table1[[#This Row],[Budget]] -> -0.63952365 | X299: =IF(L299="","", IF(L299<Predictability!$B$1,"Low", IF(L299<=Predictability!$B$2,"Mid","High"))) -> Mid | Y299: =IF(W299>=0.5,1,0) -> 0
A300: Babe | B300: Miriam Margolyes | C300: Chris Noonan | D300: 405 | E300: 1185 | F300: 108 | G300: 5000 | H300: 6.8 | I300: 79 | J300: 91 | K300: 66600000 | L300: 30000000 | M300: =VLOOKUP(A300,Sheet2!$A$1:G4024,2,0) -> 34858 | N300: =VLOOKUP(A300,Sheet2!$A$1:G4024,3,0) -> Color | O300: =VLOOKUP(A300,Sheet2!$A$1:G4024,4,0) -> Comedy | P300: =VLOOKUP(A300,Sheet2!$A$1:G4024,5,0) -> English | Q300: =VLOOKUP(A300,Sheet2!$A$1:G4024,6,0) -> Australia | R300: =VLOOKUP(A300,Sheet2!$A$1:G4024,7,0) -> G | S300: =IF(Table1[[#This Row],[Language]]="English","English","Other language") -> English | T300: =Table1[[#This Row],[Gross Revenue]]-Table1[[#This Row],[Budget]] -> 36600000 | U300: =(Table1[[#This Row],[Gross Revenue]]/Table1[[#This Row],[Budget]])-1 -> 1.22 | V300: =IF(J300="","",IF(J300<90,"<90 minutes",IF(J300<=110,"90-110 minutes",IF(J300<=130,"111-130 minutes",IF(J300<=150,"131-150 minutes",">150 minutes"))))) -> 90-110 minutes | W300: =Table1[[#This Row],[Profit]]/Table1[[#This Row],[Budget]] -> 1.22 | X300: =IF(L300="","", IF(L300<Predictability!$B$1,"Low", IF(L300<=Predictability!$B$2,"Mid","High"))) -> Mid | Y300: =IF(W300>=0.5,1,0) -> 1
A301: Babe: Pig in the City | B301: Adam Goldberg | C301: George Miller | D301: 1000 | E301: 2521 | F301: 750 | G301: 964 | H301: 5.8 | I301: 61 | J301: 97 | K301: 18318000 | L301: 80000000 | M301: =VLOOKUP(A301,Sheet2!$A$1:G4025,2,0) -> 35864 | N301: =VLOOKUP(A301,Sheet2!$A$1:G4025,3,0) -> Color | O301: =VLOOKUP(A301,Sheet2!$A$1:G4025,4,0) -> Adventure | P301: =VLOOKUP(A301,Sheet2!$A$1:G4025,5,0) -> English | Q301: =VLOOKUP(A301,Sheet2!$A$1:G4025,6,0) -> Australia | R301: =VLOOKUP(A301,Sheet2!$A$1:G4025,7,0) -> G | S301: =IF(Table1[[#This Row],[Language]]="English","English","Other language") -> English | T301: =Table1[[#This Row],[Gross Revenue]]-Table1[[#This Row],[Budget]] -> -61682000 | U301: =(Table1[[#This Row],[Gross Revenue]]/Table1[[#This Row],[Budget]])-1 -> -0.771025 | V301: =IF(J301="","",IF(J301<90,"<90 minutes",IF(J301<=110,"90-110 minutes",IF(J301<=130,"111-130 minutes",IF(J301<=150,"131-150 minutes",">150 minutes"))))) -> 90-110 minutes | W301: =Table1[[#This Row],[Profit]]/Table1[[#This Row],[Budget]] -> -0.771025 | X301: =IF(L301="","", IF(L301<Predictability!$B$1,"Low", IF(L301<=Predictability!$B$2,"Mid","High"))) -> High | Y301: =IF(W301>=0.5,1,0) -> 0
A302: Babel | B302: Brad Pitt | C302: Alejandro G. IÃ±Ã¡rritu | D302: 11000 | E302: 11248 | F302: 0 | G302: 0 | H302: 7.5 | I302: 285 | J302: 143 | K302: 34300771 | L302: 25000000 | M302: =VLOOKUP(A302,Sheet2!$A$1:G4026,2,0) -> 38804 | N302: =VLOOKUP(A302,Sheet2!$A$1:G4026,3,0) -> Color | O302: =VLOOKUP(A302,Sheet2!$A$1:G4026,4,0) -> Drama | P302: =VLOOKUP(A302,Sheet2!$A$1:G4026,5,0) -> English | Q302: =VLOOKUP(A302,Sheet2!$A$1:G4026,6,0) -> France | R302: =VLOOKUP(A302,Sheet2!$A$1:G4026,7,0) -> R | S302: =IF(Table1[[#This Row],[Language]]="English","English","Other language") -> English | T302: =Table1[[#This Row],[Gross Revenue]]-Table1[[#This Row],[Budget]] -> 9300771 | U302: =(Table1[[#This Row],[Gross Revenue]]/Table1[[#This Row],[Budget]])-1 -> 0.37203084 | V302: =IF(J302="","",IF(J302<90,"<90 minutes",IF(J302<=110,"90-110 minutes",IF(J302<=130,"111-130 minutes",IF(J302<=150,"131-150 minutes",">150 minutes"))))) -> 131-150 minutes | W302: =Table1[[#This Row],[Profit]]/Table1[[#This Row],[Budget]] -> 0.37203084 | X302: =IF(L302="","", IF(L302<Predictability!$B$1,"Low", IF(L302<=Predictability!$B$2,"Mid","High"))) -> Mid | Y302: =IF(W302>=0.5,1,0) -> 0
A303: Baby Boy | B303: Mo'Nique | C303: John Singleton | D303: 939 | E303: 3107 | F303: 309 | G303: 1000 | H303: 6.4 | I303: 41 | J303: 130 | K303: 28734552 | L303: 16000000 | M303: =VLOOKUP(A303,Sheet2!$A$1:G4027,2,0) -> 37100 | N303: =VLOOKUP(A303,Sheet2!$A$1:G4027,3,0) -> Black and White | O303: =VLOOKUP(A303,Sheet2!$A$1:G4027,4,0) -> Crime | P303: =VLOOKUP(A303,Sheet2!$A$1:G4027,5,0) -> English | Q303: =VLOOKUP(A303,Sheet2!$A$1:G4027,6,0) -> USA | R303: =VLOOKUP(A303,Sheet2!$A$1:G4027,7,0) -> R | S303: =IF(Table1[[#This Row],[Language]]="English","English","Other language") -> English | T303: =Table1[[#This Row],[Gross Revenue]]-Table1[[#This Row],[Budget]] -> 12734552 | U303: =(Table1[[#This Row],[Gross Revenue]]/Table1[[#This Row],[Budget]])-1 -> 0.7959095 | V303: =IF(J303="","",IF(J303<90,"<90 minutes",IF(J303<=110,"90-110 minutes",IF(J303<=130,"111-130 minutes",IF(J303<=150,"131-150 minutes",">150 minutes"))))) -> 111-130 minutes | W303: =Table1[[#This Row],[Profit]]/Table1[[#This Row],[Budget]] -> 0.7959095 | X303: =IF(L303="","", IF(L303<Predictability!$B$1,"Low", IF(L303<=Predictability!$B$2,"Mid","High"))) -> Mid | Y303: =IF(W303>=0.5,1,0) -> 1
A304: Baby Geniuses | B304: Kathleen Turner | C304: Bob Clark | D304: 899 | E304: 2936 | F304: 84 | G304: 0 | H304: 2.5 | I304: 45 | J304: 97 | K304: 27141959 | L304: 18000000 | M304: =VLOOKUP(A304,Sheet2!$A$1:G4028,2,0) -> 36362 | N304: =VLOOKUP(A304,Sheet2!$A$1:G4028,3,0) -> Color | O304: =VLOOKUP(A304,Sheet2!$A$1:G4028,4,0) -> Comedy | P304: =VLOOKUP(A304,Sheet2!$A$1:G4028,5,0) -> English | Q304: =VLOOKUP(A304,Sheet2!$A$1:G4028,6,0) -> USA | R304: =VLOOKUP(A304,Sheet2!$A$1:G4028,7,0) -> PG | S304: =IF(Table1[[#This Row],[Language]]="English","English","Other language") -> English | T304: =Table1[[#This Row],[Gross Revenue]]-Table1[[#This Row],[Budget]] -> 9141959 | U304: =(Table1[[#This Row],[Gross Revenue]]/Table1[[#This Row],[Budget]])-1 -> 0.50788661 | V304: =IF(J304="","",IF(J304<90,"<90 minutes",IF(J304<=110,"90-110 minutes",IF(J304<=130,"111-130 minutes",IF(J304<=150,"131-150 minutes",">150 minutes"))))) -> 90-110 minutes | W304: =Table1[[#This Row],[Profit]]/Table1[[#This Row],[Budget]] -> 0.50788661 | X304: =IF(L304="","", IF(L304<Predictability!$B$1,"Low", IF(L304<=Predictability!$B$2,"Mid","High"))) -> Mid | Y304: =IF(W304>=0.5,1,0) -> 1
A305: Baby Mama | B305: Tina Fey | C305: Michael McCullers | D305: 2000 | E305: 6930 | F305: 5 | G305: 0 | H305: 6 | I305: 145 | J305: 99 | K305: 60269340 | L305: 30000000 | M305: =VLOOKUP(A305,Sheet2!$A$1:G4029,2,0) -> 39645 | N305: =VLOOKUP(A305,Sheet2!$A$1:G4029,3,0) -> Color | O305: =VLOOKUP(A305,Sheet2!$A$1:G4029,4,0) -> Comedy | P305: =VLOOKUP(A305,Sheet2!$A$1:G4029,5,0) -> English | Q305: =VLOOKUP(A305,Sheet2!$A$1:G4029,6,0) -> USA | R305: =VLOOKUP(A305,Sheet2!$A$1:G4029,7,0) -> PG-13 | S305: =IF(Table1[[#This Row],[Language]]="English","English","Other language") -> English | T305: =Table1[[#This Row],[Gross Revenue]]-Table1[[#This Row],[Budget]] -> 30269340 | U305: =(Table1[[#This Row],[Gross Revenue]]/Table1[[#This Row],[Budget]])-1 -> 1.008978 | V305: =IF(J305="","",IF(J305<90,"<90 minutes",IF(J305<=110,"90-110 minutes",IF(J305<=130,"111-130 minutes",IF(J305<=150,"131-150 minutes",">150 minutes"))))) -> 90-110 minutes | W305: =Table1[[#This Row],[Profit]]/Table1[[#This Row],[Budget]] -> 1.008978 | X305: =IF(L305="","", IF(L305<Predictability!$B$1,"Low", IF(L305<=Predictability!$B$2,"Mid","High"))) -> Mid | Y305: =IF(W305>=0.5,1,0) -> 1
A306: Babylon A.D. | B306: Vin Diesel | C306: Mathieu Kassovitz | D306: 14000 | E306: 15990 | F306: 326 | G306: 0 | H306: 5.6 | I306: 164 | J306: 101 | K306: 22531698 | L306: 70000000 | M306: =VLOOKUP(A306,Sheet2!$A$1:G4030,2,0) -> 39601 | N306: =VLOOKUP(A306,Sheet2!$A$1:G4030,3,0) -> Color | O306: =VLOOKUP(A306,Sheet2!$A$1:G4030,4,0) -> Action | P306: =VLOOKUP(A306,Sheet2!$A$1:G4030,5,0) -> English | Q306: =VLOOKUP(A306,Sheet2!$A$1:G4030,6,0) -> France | R306: =VLOOKUP(A306,Sheet2!$A$1:G4030,7,0) -> PG-13 | S306: =IF(Table1[[#This Row],[Language]]="English","English","Other language") -> English | T306: =Table1[[#This Row],[Gross Revenue]]-Table1[[#This Row],[Budget]] -> -47468302 | U306: =(Table1[[#This Row],[Gross Revenue]]/Table1[[#This Row],[Budget]])-1 -> -0.6781186 | V306: =IF(J306="","",IF(J306<90,"<90 minutes",IF(J306<=110,"90-110 minutes",IF(J306<=130,"111-130 minutes",IF(J306<=150,"131-150 minutes",">150 minutes"))))) -> 90-110 minutes | W306: =Table1[[#This Row],[Profit]]/Table1[[#This Row],[Budget]] -> -0.6781186 | X306: =IF(L306="","", IF(L306<Predictability!$B$1,"Low", IF(L306<=Predictability!$B$2,"Mid","High"))) -> High | Y306: =IF(W306>=0.5,1,0) -> 0
A307: Baby's Day Out | B307: Joe Mantegna | C307: Patrick Read Johnson | D307: 1000 | E307: 2949 | F307: 32 | G307: 0 | H307: 5.9 | I307: 22 | J307: 99 | K307: 16671505 | L307: 50000000 | M307: =VLOOKUP(A307,Sheet2!$A$1:G4031,2,0) -> 34530 | N307: =VLOOKUP(A307,Sheet2!$A$1:G4031,3,0) -> Color | O307: =VLOOKUP(A307,Sheet2!$A$1:G4031,4,0) -> Adventure | P307: =VLOOKUP(A307,Sheet2!$A$1:G4031,5,0) -> English | Q307: =VLOOKUP(A307,Sheet2!$A$1:G4031,6,0) -> USA | R307: =VLOOKUP(A307,Sheet2!$A$1:G4031,7,0) -> PG | S307: =IF(Table1[[#This Row],[Language]]="English","English","Other language") -> English | T307: =Table1[[#This Row],[Gross Revenue]]-Table1[[#This Row],[Budget]] -> -33328495 | U307: =(Table1[[#This Row],[Gross Revenue]]/Table1[[#This Row],[Budget]])-1 -> -0.6665699 | V307: =IF(J307="","",IF(J307<90,"<90 minutes",IF(J307<=110,"90-110 minutes",IF(J307<=130,"111-130 minutes",IF(J307<=150,"131-150 minutes",">150 minutes"))))) -> 90-110 minutes | W307: =Table1[[#This Row],[Profit]]/Table1[[#This Row],[Budget]] -> -0.6665699 | X307: =IF(L307="","", IF(L307<Predictability!$B$1,"Low", IF(L307<=Predictability!$B$2,"Mid","High"))) -> Mid | Y307: =IF(W307>=0.5,1,0) -> 0
A308: Bachelorette | B308: Kirsten Dunst | C308: Leslye Headland | D308: 4000 | E308: 8353 | F308: 21 | G308: 0 | H308: 5.3 | I308: 156 | J308: 87 | K308: 418268 | L308: 3000000 | M308: =VLOOKUP(A308,Sheet2!$A$1:G4032,2,0) -> 41185 | N308: =VLOOKUP(A308,Sheet2!$A$1:G4032,3,0) -> Color | O308: =VLOOKUP(A308,Sheet2!$A$1:G4032,4,0) -> Comedy | P308: =VLOOKUP(A308,Sheet2!$A$1:G4032,5,0) -> English | Q308: =VLOOKUP(A308,Sheet2!$A$1:G4032,6,0) -> USA | R308: =VLOOKUP(A308,Sheet2!$A$1:G4032,7,0) -> R | S308: =IF(Table1[[#This Row],[Language]]="English","English","Other language") -> English | T308: =Table1[[#This Row],[Gross Revenue]]-Table1[[#This Row],[Budget]] -> -2581732 | U308: =(Table1[[#This Row],[Gross Revenue]]/Table1[[#This Row],[Budget]])-1 -> -0.86057733 | V308: =IF(J308="","",IF(J308<90,"<90 minutes",IF(J308<=110,"90-110 minutes",IF(J308<=130,"111-130 minutes",IF(J308<=150,"131-150 minutes",">150 minutes"))))) -> <90 minutes | W308: =Table1[[#This Row],[Profit]]/Table1[[#This Row],[Budget]] -> -0.86057733 | X308: =IF(L308="","", IF(L308<Predictability!$B$1,"Low", IF(L308<=Predictability!$B$2,"Mid","High"))) -> Low | Y308: =IF(W308>=0.5,1,0) -> 0
...

Sheet Predictability
A1: P25 Budget | B1: =_xlfn.PERCENTILE.INC(Main!L:L,0.25) -> 9000000 | D1: Mid budget
A2: P75 Budget | B2: =_xlfn.PERCENTILE.INC(Main!L:L,0.75) -> 50000000 | D2: 9000000-50000000
A6: Budget_Tier | B6: r: Cast → ROI | C6: r: Movie → ROI | D6: r: Lead_Actor → ROI | E6: r: Director → ROI
A7: Low | B7: {=_xlfn.LET( _xlpm.tier,$A7, _xlpm.x,_xlfn._xlws.FILTER(Main!$E:$E,(Main!$X:$X=_xlpm.tier)*ISNUMBER(Main!$E:$E)*ISNUMBER(Main!$W:$W)), _xlpm.y,_xlfn._xlws.FILTER(Main!$W:$W,(Main!$X:$X=_xlpm.tier)*ISNUMBER(Main!$E:$E)*ISNUMBER(Main!$W:$W)), IFERROR(CORREL(_xlpm.x,_xlpm.y),"") )} -> -0.025455883 | C7: {=_xlfn.LET( _xlpm.tier,$A7, _xlpm.x,_xlfn._xlws.FILTER(Main!$G:$G,(Main!$X:$X=_xlpm.tier)*ISNUMBER(Main!$G:$G)*ISNUMBER(Main!$W:$W)), _xlpm.y,_xlfn._xlws.FILTER(Main!$W:$W,(Main!$X:$X=_xlpm.tier)*ISNUMBER(Main!$G:$G)*ISNUMBER(Main!$W:$W)), IFERROR(CORREL(_xlpm.x,_xlpm.y),"") )} -> 0.012575939 | D7: {=_xlfn.LET( _xlpm.tier,$A7, _xlpm.x,_xlfn._xlws.FILTER(Main!$D:$D,(Main!$X:$X=_xlpm.tier)*ISNUMBER(Main!$D:$D)*ISNUMBER(Main!$W:$W)), _xlpm.y,_xlfn._xlws.FILTER(Main!$W:$W,(Main!$X:$X=_xlpm.tier)*ISNUMBER(Main!$D:$D)*ISNUMBER(Main!$W:$W)), IFERROR(CORREL(_xlpm.x,_xlpm.y),"") )} -> -0.020580915 | E7: {=_xlfn.LET( _xlpm.tier,$A7, _xlpm.x,_xlfn._xlws.FILTER(Main!$F:$F,(Main!$X:$X=_xlpm.tier)*ISNUMBER(Main!$F:$F)*ISNUMBER(Main!$W:$W)), _xlpm.y,_xlfn._xlws.FILTER(Main!$W:$W,(Main!$X:$X=_xlpm.tier)*ISNUMBER(Main!$F:$F)*ISNUMBER(Main!$W:$W)), IFERROR(CORREL(_xlpm.x,_xlpm.y),"") )} -> -0.0068706769
A8: Mid | B8: {=_xlfn.LET( _xlpm.tier,$A8, _xlpm.x,_xlfn._xlws.FILTER(Main!$E:$E,(Main!$X:$X=_xlpm.tier)*ISNUMBER(Main!$E:$E)*ISNUMBER(Main!$W:$W)), _xlpm.y,_xlfn._xlws.FILTER(Main!$W:$W,(Main!$X:$X=_xlpm.tier)*ISNUMBER(Main!$E:$E)*ISNUMBER(Main!$W:$W)), IFERROR(CORREL(_xlpm.x,_xlpm.y),"") )} -> 0.042609917 | C8: {=_xlfn.LET( _xlpm.tier,$A8, _xlpm.x,_xlfn._xlws.FILTER(Main!$G:$G,(Main!$X:$X=_xlpm.tier)*ISNUMBER(Main!$G:$G)*ISNUMBER(Main!$W:$W)), _xlpm.y,_xlfn._xlws.FILTER(Main!$W:$W,(Main!$X:$X=_xlpm.tier)*ISNUMBER(Main!$G:$G)*ISNUMBER(Main!$W:$W)), IFERROR(CORREL(_xlpm.x,_xlpm.y),"") )} -> 0.17748557 | D8: {=_xlfn.LET( _xlpm.tier,$A8, _xlpm.x,_xlfn._xlws.FILTER(Main!$D:$D,(Main!$X:$X=_xlpm.tier)*ISNUMBER(Main!$D:$D)*ISNUMBER(Main!$W:$W)), _xlpm.y,_xlfn._xlws.FILTER(Main!$W:$W,(Main!$X:$X=_xlpm.tier)*ISNUMBER(Main!$D:$D)*ISNUMBER(Main!$W:$W)), IFERROR(CORREL(_xlpm.x,_xlpm.y),"") )} -> 0.03567474 | E8: {=_xlfn.LET( _xlpm.tier,$A8, _xlpm.x,_xlfn._xlws.FILTER(Main!$F:$F,(Main!$X:$X=_xlpm.tier)*ISNUMBER(Main!$F:$F)*ISNUMBER(Main!$W:$W)), _xlpm.y,_xlfn._xlws.FILTER(Main!$W:$W,(Main!$X:$X=_xlpm.tier)*ISNUMBER(Main!$F:$F)*ISNUMBER(Main!$W:$W)), IFERROR(CORREL(_xlpm.x,_xlpm.y),"") )} -> 0.10865116
A9: High | B9: {=_xlfn.LET( _xlpm.tier,$A9, _xlpm.x,_xlfn._xlws.FILTER(Main!$E:$E,(Main!$X:$X=_xlpm.tier)*ISNUMBER(Main!$E:$E)*ISNUMBER(Main!$W:$W)), _xlpm.y,_xlfn._xlws.FILTER(Main!$W:$W,(Main!$X:$X=_xlpm.tier)*ISNUMBER(Main!$E:$E)*ISNUMBER(Main!$W:$W)), IFERROR(CORREL(_xlpm.x,_xlpm.y),"") )} -> 0.14691975 | C9: {=_xlfn.LET( _xlpm.tier,$A9, _xlpm.x,_xlfn._xlws.FILTER(Main!$G:$G,(Main!$X:$X=_xlpm.tier)*ISNUMBER(Main!$G:$G)*ISNUMBER(Main!$W:$W)), _xlpm.y,_xlfn._xlws.FILTER(Main!$W:$W,(Main!$X:$X=_xlpm.tier)*ISNUMBER(Main!$G:$G)*ISNUMBER(Main!$W:$W)), IFERROR(CORREL(_xlpm.x,_xlpm.y),"") )} -> 0.21787526 | D9: {=_xlfn.LET( _xlpm.tier,$A9, _xlpm.x,_xlfn._xlws.FILTER(Main!$D:$D,(Main!$X:$X=_xlpm.tier)*ISNUMBER(Main!$D:$D)*ISNUMBER(Main!$W:$W)), _xlpm.y,_xlfn._xlws.FILTER(Main!$W:$W,(Main!$X:$X=_xlpm.tier)*ISNUMBER(Main!$D:$D)*ISNUMBER(Main!$W:$W)), IFERROR(CORREL(_xlpm.x,_xlpm.y),"") )} -> 0.082398348 | E9: {=_xlfn.LET( _xlpm.tier,$A9, _xlpm.x,_xlfn._xlws.FILTER(Main!$F:$F,(Main!$X:$X=_xlpm.tier)*ISNUMBER(Main!$F:$F)*ISNUMBER(Main!$W:$W)), _xlpm.y,_xlfn._xlws.FILTER(Main!$W:$W,(Main!$X:$X=_xlpm.tier)*ISNUMBER(Main!$F:$F)*ISNUMBER(Main!$W:$W)), IFERROR(CORREL(_xlpm.x,_xlpm.y),"") )} -> 0.10065681

Sheet top leads actor by FB likes R
A1: Years (Release Date) | B1: (Multiple Items)
A3: Row Labels | B3: Count of Title | C3: Average of Median ROI | D3: Average of Lead Actor FB Likes | E3: Average of IMDb Score (1-10)
A4: Mackenzie Foy | B4: 2 | C4: 1.1909079 | D4: 6000 | E4: 7.7
A5: Bojana Novakovic | B5: 3 | C5: 0.79144341 | D5: 2000 | E5: 6.5
A6: Bradley Cooper | B6: 12 | C6: 0.21717823 | D6: 14000 | E6: 6.4666667
A7: Larry David | B7: 2 | C7: 0.19178668 | D7: 860 | E7: 7.4
A8: ZoÃ« Kravitz | B8: 2 | C8: 0.19178668 | D8: 943 | E8: 6.75
A9: Rob Riggle | B9: 2 | C9: 0.19178668 | D9: 839 | E9: 6.4
A10: Mark Duplass | B10: 2 | C10: 0.19178668 | D10: 830 | E10: 6.65
A11: Busy Philipps | B11: 2 | C11: 0.19178668 | D11: 1000 | E11: 6.45
A12: Clifton Collins Jr. | B12: 3 | C12: 0.19178668 | D12: 968 | E12: 6.5
A13: Janeane Garofalo | B13: 2 | C13: 0.19178668 | D13: 1000 | E13: 6.75
A14: Zachary Gordon | B14: 3 | C14: 0.16694755 | D14: 975 | E14: 6.6333333
A15: Alan Rickman | B15: 2 | C15: 0.15452798 | D15: 25000 | E15: 7.15
... A74: Grand Total | B74: 381 | C74: 0.070021487 | D74: 13399.919 | E74: 6.7965879

Sheet top leads actor by FB likes
A1: Years (Release Date) | B1: (Multiple Items)
A3: Row Labels | B3: Count of Title | C3: Average of Lead Actor FB Likes | D3: Average of IMDb Score (1-10)
A4: Johnny Depp | B4: 16 | C4: 40000 | D4: 6.55
A5: Jennifer Lawrence | B5: 13 | C5: 34000 | D5: 7.0692308
A6: Ryan Gosling | B6: 10 | C6: 33000 | D6: 7.18
A7: Leonardo DiCaprio | B7: 11 | C7: 29000 | D7: 7.8636364
A8: Tom Hardy | B8: 7 | C8: 27000 | D8: 7.4
A9: Chris Hemsworth | B9: 13 | C9: 26000 | D9: 6.9153846
A10: Alan Rickman | B10: 2 | C10: 25000 | D10: 7.15
A11: J.K. Simmons | B11: 19 | C11: 24000 | D11: 6.7368421
A12: Paul Walker | B12: 7 | C12: 23000 | D12: 6.6857143
A13: Christian Bale | B13: 12 | C13: 23000 | D13: 7.4666667
A14: Joseph Gordon-Levitt | B14: 12 | C14: 23000 | D14: 6.8833333
A15: Philip Seymour Hoffman | B15: 7 | C15: 22000 | D15: 7.2571429
... A143: Terry Pheto | B143: 2 | C143: 113 | D143: 7.2
A144: (blank) | B144: 2 | D144: 7.3
A145: Grand Total | B145: 734 | C145: 13272.003 | D145: 6.8666213

Sheet filter table of genere
A1: Years (Release Date) | B1: (Multiple Items)
A2: Country | B2: USA
A3: Is _English | B3: English
A5: Row Labels | B5: Count of Title | C5: Median Of Profit | D5: Average of Profit | E5: Average of Budget | F5: Median of ROI
A6: Comedy | B6: 399 | C6: 1637763 | D6: 14247390 | E6: 25497178 | F6: 0.19178668
A7: Adventure | B7: 156 | C7: 3892693.5 | D7: 26423027 | E7: 81523397 | F7: 0.11726929
A8: Grand Total | B8: 555 | C8: 2271581.3 | D8: 17669731 | E8: 41245088 | F8: 0.17084125

Sheet top leads dirctors
A1: Years (Release Date) | B1: (Multiple Items)
A3: Row Labels | B3: Median Of ROI | C3: Average of Lead Actor FB Likes | D3: Average of IMDb Score (1-10) | E3: Count of Title
A4: Adam McKay | B4: 0.071817633 | C4: 118666.67 | D4: 6.9166667 | E4: 6
A5: Gore Verbinski | B5: 0.033388512 | C5: 33714.286 | D5: 6.9857143 | E5: 7
A6: Martin Scorsese | B6: 0.0011990187 | C6: 27000 | D6: 7.8833333 | E6: 6
A7: Francis Lawrence | B7: 0.029901168 | C7: 26600 | D7: 7 | E7: 5
A8: David O. Russell | B8: 0.05595697 | C8: 26200 | D8: 7.26 | E8: 5
